{
  "comments": [
    {
      "key": {
        "uuid": "7e79e04e_151eae93",
        "filename": "resources/libraries/python/LoadBalancerUtil.py",
        "patchSetId": 78
      },
      "lineNbr": 120,
      "author": {
        "id": 1263
      },
      "writtenOn": "2019-12-19T12:04:25Z",
      "side": 1,
      "message": "u\"ip4\"\n\nThis is masking another loadbalancer breakage that happened between here and now.",
      "range": {
        "startLine": 120,
        "startChar": 41,
        "endLine": 120,
        "endChar": 46
      },
      "revId": "d68951ac245150eeefa6e0f4156e4c1b5c9e9325",
      "serverId": "6d2eb258-4fe2-443e-8a38-ca81da23d4c2",
      "unresolved": true
    }
  ]
}